Workbook

Sheet Saisies
A1: Saisies — votre situation
A2: Cellules bleues à renseigner. Le profil Anah et les résultats se calculent automatiquement.
A4: Votre foyer
A5: Nombre de personnes au foyer | B5: 2 | C5: Adultes + enfants à charge (1 à 6).
A6: Revenu fiscal de référence (€/an) | B6: 40000 | C6: Page 1 de l'avis d'imposition.
A7: Zone géographique | B7: hors_idf | C7: hors_idf | idf (plafonds RFR + élevés en IDF).
A9: Votre logement
A10: Statut | B10: po | C10: po = propriétaire occupant | pb = bailleur | loc = locataire.
A11: Type | B11: maison | C11: maison | appt.
A12: Surface (m²) | B12: 150 | C12: Surface chauffée.
A13: DPE actuel | B13: G | C13: A à G. E/F/G = passoires → aides bonifiées.
A14: Chauffage actuel | B14: gaz | C14: gaz | fioul | elec | bois.
A15: Eau chaude sanitaire actuelle | B15: meme | C15: meme | ballon_elec | cet.
A16: Projet de travaux | B16: pac_aireau | C16: pac_aireau | pac_geo | cet_only | reno_ampleur | pv_autoconso | aucun_log.
A18: Votre mobilité
A19: Véhicule actuel | B19: diesel | C19: essence | diesel | hybride | aucun.
A20: Kilométrage annuel (km) | B20: 20000 | C20: Distance totale parcourue par an.
A21: Mode de déplacement principal | B21: domicile | C21: domicile (recharge maison) | mixte (long trajets) | urbain (recharge publique).
A22: Projet de véhicule | B22: ve_neuf | C22: ve_neuf | ve_occ | leasing_social | aucun_mob.
A23: Borne de recharge à domicile | B23: oui | C23: oui (wallbox) | copro (prime ADVENIR) | non.
A25: Paramètres de simulation
A26: Horizon de cumul (années) | B26: 20 | C26: Entre 15 et 25 ans.
A28: Solutions à inclure dans le bilan étalé
A29: Inclure PAC air/eau ? | B29: OUI | C29: Bascule du chauffage actuel vers PAC.
A30: Inclure rénovation d'ampleur ? | B30: NON | C30: Bouquet de travaux gain ≥ 2 classes DPE.
A31: Inclure VE neuf ? | B31: OUI | C31: Bascule véhicule thermique → électrique.
A32: Inclure photovoltaïque ? | B32: NON | C32: Installation 3 kWc autoconsommation.
A34: Année de démarrage par chantier (étalement)
A35: Année de démarrage PAC | B35: 1 | C35: 1 = première année de l'horizon.
A36: Année de démarrage Réno | B36: 1
A37: Année de démarrage VE | B37: 1
A38: Année de démarrage PV | B38: 1

Sheet Hypothèses
A1: Hypothèses — Passer à l'électrique 2026
A2: Cellules bleues : valeurs modifiables. Tout le classeur recalcule automatiquement.
A4: Prix des énergies (€/kWh PCI ou €/L)
A5: Électricité — heures pleines (€/kWh) | B5: 0.2516 | G5: Tarif réglementé EDF base — CRE
A6: Électricité — heures creuses (€/kWh) | B6: 0.2068 | G6: Tarif réglementé EDF HC — CRE
A7: Gaz (€/kWh PCS) | B7: 0.1162 | G7: Prix repère gaz — CRE 2026
A8: Fioul (€/kWh PCI) | B8: 0.135 | G8: ≈ 1,35 €/L sur 10 kWh/L
A9: Bois / pellets (€/kWh) | B9: 0.075 | G9: Moyenne 2026 — FNB
A10: Essence SP95-E10 (€/L) | B10: 1.95 | G10: Moyenne 2026 — DGEC
A11: Diesel (€/L) | B11: 1.8 | G11: Moyenne 2026 — DGEC
A13: COP des PAC & consommation véhicules
A14: COP PAC air/eau | B14: 3.5 | G14: ADEME / Uniclima
A15: COP PAC géothermique | B15: 4.5 | G15: ADEME
A16: COP chauffe-eau thermo (CET) | B16: 2.8 | G16: ADEME
A17: Conso véhicule thermique (L/100 km) | B17: 6.5 | G17: WLTP segment C
A18: Conso véhicule électrique (kWh/100 km) | B18: 17 | G18: WLTP segment C
A19: Conso ECS (kWh/personne/an) | B19: 1200 | G19: Hyp. moyenne foyer
A21: Consommation chauffage + ECS par classe DPE (kWh/m²/an)
A22: Classe | B22: kWh/m²/an
A23: A | B23: 50 | G23: Seuils DPE 2025 (méthode 3CL) — arrêté 31 mars 2021
A24: B | B24: 90
A25: C | B25: 150
A26: D | B26: 230
A27: E | B27: 330
A28: F | B28: 450
A29: G | B29: 600
A31: Coûts d'installation moyens (€ TTC clé en main)
A32: PAC air/eau | B32: 14000 | G32: Devis 2025-2026 métropole
A33: PAC géothermique | B33: 22000 | G33: Devis 2025-2026
A34: Chauffe-eau thermodynamique (CET seul) | B34: 3500 | G34: Devis 2025-2026
A35: Rénovation d'ampleur (2 sauts DPE) | B35: 45000 | G35: Ordre de grandeur Anah
A36: Photovoltaïque 3 kWc autoconsommation | B36: 9000 | G36: Devis 2025-2026
A38: Véhicule électrique — prix & primes
A39: Prix moyen VE neuf (€) | B39: 32000 | G39: Hyp. segment B/C 2026
A40: Prix moyen thermique équivalent (€) | B40: 23000 | G40: Hyp. segment B/C 2026
A41: Surcoût VE vs thermique (€) | B41: =Hypothèses!$B$39-Hypothèses!$B$40 -> 9000 | G41: Hyp. : ménage rachète un véhicule de toute façon
A42: Surbonus batterie fabriquée en UE (€) | B42: 1500 | G42: Score environnemental ADEME
A43: Prime conversion diesel modeste (€) | B43: 1500 | G43: Revenus modestes + mise au rebut
A44: Leasing social — gain annuel (€/an) | B44: 2400 | G44: (300−100) × 12 vs LLD marché
A46: Borne de recharge à domicile
...

Sheet Calculs
A1: Calculs intermédiaires
A2: Les cellules ci-dessous sont des formules — ne modifiez que Saisies et Hypothèses.
A4: 1. Profil Anah
A5: Personnes (1-6, borné) | B5: =MIN(MAX(Saisies!$B$5,1),6) -> 2 | C5: Borne basse 1 et borne haute 6 pour les tables RFR.
A6: Seuil RFR — bleu | B6: =IF(Saisies!$B$7="idf",INDEX(Hypothèses!$A$117:$D$122,Calculs!$B$5,2),INDEX(Hypothèses!$A$108:$D$113,Calculs!$B$5,2)) -> 24875 | C6: Plafond très modestes selon zone × nb pers.
A7: Seuil RFR — jaune | B7: =IF(Saisies!$B$7="idf",INDEX(Hypothèses!$A$117:$D$122,Calculs!$B$5,3),INDEX(Hypothèses!$A$108:$D$113,Calculs!$B$5,3)) -> 31889
A8: Seuil RFR — violet | B8: =IF(Saisies!$B$7="idf",INDEX(Hypothèses!$A$117:$D$122,Calculs!$B$5,4),INDEX(Hypothèses!$A$108:$D$113,Calculs!$B$5,4)) -> 44907
A9: Profil Anah | B9: =IF(Saisies!$B$6<=Calculs!$B$6,"bleu",IF(Saisies!$B$6<=Calculs!$B$7,"jaune",IF(Saisies!$B$6<=Calculs!$B$8,"violet","rose"))) -> violet | C9: Bleu / jaune / violet / rose.
A10: Index profil (1=bleu .. 4=rose) | B10: =MATCH(Calculs!$B$9,{"bleu","jaune","violet","rose"},0) -> 3 | C10: Sert aux lookups MPR/CEE.
A11: Parts fiscales (estim.) | B11: =IF(Saisies!$B$5<=1,1,IF(Saisies!$B$5=2,2,2+(Saisies!$B$5-2)*0.5)) -> 2 | C11: 1 adulte → 1 part, 2 adultes → 2 parts, +0,5 par enfant.
A12: RFR / part (€) | B12: =Saisies!$B$6/Calculs!$B$11 -> 20000 | C12: Détermine la tranche prime VPE.
A13: Prime VPE selon RFR/part (€) | B13: =INDEX(Hypothèses!$A$100:$B$103,IFERROR(MATCH(Calculs!$B$12,INDEX(Hypothèses!$A$100:$B$103,,1),1),0)+1,2) -> 2000 | C13: Tranche où le plafond ≥ RFR/part (recherche approchée).
A15: 2. Coût actuel — situation de référence
A16: Prix énergie chauffage actuel (€/kWh) | B16: =IF(Saisies!$B$14="gaz",Hypothèses!$B$7,IF(Saisies!$B$14="fioul",Hypothèses!$B$8,IF(Saisies!$B$14="bois",Hypothèses!$B$9,Hypothèses!$B$5))) -> 0.1162 | C16: Élec heures pleines si chauffage électrique.
A17: Conso DPE (kWh/m²/an) | B17: =VLOOKUP(Saisies!$B$13,Hypothèses!$A$23:$B$29,2,FALSE()) -> 600 | C17: Lookup classe DPE → kWh/m²/an.
A18: Conso totale chauffage + ECS (kWh/an) | B18: =Calculs!$B$17*Saisies!$B$12 -> 90000 | C18: Conso DPE × surface.
A19: Coût chauffage actuel (€/an) | B19: =Calculs!$B$18*Calculs!$B$16 -> 10458
A20: Prix carburant actuel (€/L) | B20: =IF(Saisies!$B$19="diesel",Hypothèses!$B$11,IF(Saisies!$B$19="essence",Hypothèses!$B$10,IF(Saisies!$B$19="hybride",Hypothèses!$B$10*0.7,0))) -> 1.8 | C20: Hybride : 70 % de l'essence (hyp.).
A21: Conso véhicule actuelle (L/an) | B21: =IF(Saisies!$B$19="aucun",0,Saisies!$B$20/100*Hypothèses!$B$17) -> 1300
A22: Coût carburant actuel (€/an) | B22: =Calculs!$B$21*Calculs!$B$20 -> 2340
A23: TOTAL coût énergie actuel (€/an) | B23: =Calculs!$B$19+Calculs!$B$22 -> 12798 | C23: Chauffage + carburant.
A24: Part du revenu (%) | B24: =IF(Saisies!$B$6>0,Calculs!$B$23/Saisies!$B$6,0) -> 0.31995
A26: 3. Aides MOBILITÉ
A27: Prime CEE VPE (si VE neuf, €) | B27: =IF(Saisies!$B$22="ve_neuf",Calculs!$B$13,0) -> 2000 | C27: 0 sinon.
A28: Surbonus batterie UE (si VE neuf, €) | B28: =IF(Saisies!$B$22="ve_neuf",Hypothèses!$B$42,0) -> 1500 | C28: Score environnemental ADEME.
A29: Prime conversion diesel (€) | B29: =IF(AND(Saisies!$B$22="ve_neuf",Saisies!$B$19="diesel",OR(Calculs!$B$9="bleu",Calculs!$B$9="jaune")),Hypothèses!$B$43,0) -> 0 | C29: Diesel mis au rebut + revenus modestes.
A30: Crédit d'impôt borne domicile (€) | B30: =IF(AND(Saisies!$B$23="oui",Saisies!$B$22<>"aucun_mob"),MIN(Hypothèses!$B$47*Hypothèses!$B$48,Hypothèses!$B$49),0) -> 500 | C30: 75 % plafonné à 500 €.
A31: Prime ADVENIR copropriété (€) | B31: =IF(AND(Saisies!$B$23="copro",Saisies!$B$22<>"aucun_mob"),Hypothèses!$B$50,0) -> 0
A32: TOTAL aides mobilité (€) | B32: =Calculs!$B$27+Calculs!$B$28+Calculs!$B$29+Calculs!$B$30+Calculs!$B$31 -> 4000
A33: Prix élec recharge VE (€/kWh, selon mode) | B33: =IF(Saisies!$B$21="domicile",Hypothèses!$B$6,IF(Saisies!$B$21="urbain",0.25,0.3)) -> 0.2068 | C33: HC domicile / 0,25 urbain / 0,30 mixte.
A34: Coût élec véhicule (€/an) | B34: =IF(OR(Saisies!$B$22="aucun_mob",Saisies!$B$19="aucun"),0,Saisies!$B$20/100*Hypothèses!$B$18*Calculs!$B$33) -> 703.12
A35: Économie carburant (€/an) | B35: =IF(OR(NOT(OR(Saisies!$B$22="ve_neuf",Saisies!$B$22="ve_occ",Saisies!$B$22="leasing_social")),Saisies!$B$19="aucun"),0,Calculs!$B$22-Calculs!$B$34) -> 1636.88 | C35: Carburant économisé − électricité consommée.
A36: Gain leasing social (€/an si éligible) | B36: =IF(AND(Saisies!$B$22="leasing_social",OR(Calculs!$B$9="bleu",Calculs!$B$9="jaune")),Hypothèses!$B$44,0) -> 0 | C36: Réservé bleu/jaune.
A37: TOTAL économie mobilité (€/an) | B37: =Calculs!$B$35+Calculs!$B$36 -> 1636.88
A39: 4. Aides LOGEMENT
A40: Éligibilité logement (1 = oui) | B40: =IF(Saisies!$B$10="loc",0,1) -> 1 | C40: Locataire = pas d'aides chauffage/rénovation.
A41: MPR — PAC air/eau (si projet) | B41: =IF(AND(Calculs!$B$40=1,Saisies!$B$16="pac_aireau"),INDEX(Hypothèses!$A$62:$D$65,Calculs!$B$10,2),0) -> 3000 | C41: Lookup table MPR profil × geste.
A42: MPR — PAC géothermique (si projet) | B42: =IF(AND(Calculs!$B$40=1,Saisies!$B$16="pac_geo"),INDEX(Hypothèses!$A$62:$D$65,Calculs!$B$10,3),0) -> 0
A43: MPR — CET seul (si projet) | B43: =IF(AND(Calculs!$B$40=1,Saisies!$B$16="cet_only"),INDEX(Hypothèses!$A$62:$D$65,Calculs!$B$10,4),0) -> 0
A44: CEE — Coup de pouce (si projet PAC) | B44: =IF(AND(Calculs!$B$40=1,OR(Saisies!$B$16="pac_aireau",Saisies!$B$16="pac_geo")),IF(OR(Saisies!$B$14="gaz",Saisies!$B$14="fioul"),INDEX(Hypothèses!$A$75:$E$78,Calculs!$B$10,2),INDEX(Hypothèses!$A$75:$E$78,Calculs!$B$10,3)),0) -> 4000 | C44: Bonifié si sortie gaz/fioul, standard sinon.
...

Sheet Résultats
B1: Résultats — synthèse
B2: Tous les chiffres se mettent à jour à chaque modification des Saisies ou des Hypothèses.
B4: Indicateurs clés
B5: Situation actuelle (énergie/an) | C5: =Calculs!$B$23 -> 12798 | D5: Chauffage + carburant aux prix 2026.
B6: Part du revenu | C6: =Calculs!$B$24 -> 0.31995 | D6: Moyenne nationale ≈ 8 % (foyer DPE D à essence).
B7: Aides publiques mobilisables (État + CEE) | C7: =Calculs!$B$78 -> 11000 | D7: MaPrimeRénov' + CEE + bonus + crédit d'impôt borne + prime PV.
B8: Économie annuelle récurrente | C8: =Calculs!$B$79 -> 5625.1657 | D8: Énergie économisée après bascule.
B9: Coût total des projets engagés | C9: =Calculs!$B$77 -> 24200 | D9: Travaux logement + borne + surcoût VE.
B10: Reste à charge ménage (invest. net) | C10: =Calculs!$B$80 -> 13200 | D10: Coût projets − aides publiques.
B11: Gain net cumulé sur horizon | C11: =Calculs!$B$81 -> 99303.314 | D11: Aides + économies × horizon − coût projets.
B12: Retour sur investissement | C12: =Calculs!$B$82 -> 2.3 | D12: Reste à charge ÷ économie annuelle.
B15: Détail des dispositifs mobilisables
B16: Dispositif | C16: Montant (€) | D16: Conditions / commentaire
B17: ── MOBILITÉ ──
B18: Prime CEE « VPE » | C18: =Calculs!$B$27 -> 2000 | D18: Si VE neuf ; tranche RFR/part.
B19: Surbonus batterie UE | C19: =Calculs!$B$28 -> 1500 | D19: Si VE neuf ; score env. ADEME.
B20: Prime à la conversion (diesel) | C20: =Calculs!$B$29 -> 0 | D20: Diesel mis au rebut + revenus modestes.
B21: Crédit d'impôt borne domicile | C21: =Calculs!$B$30 -> 500 | D21: 75 % plafonné à 500 €.
B22: Prime ADVENIR copropriété | C22: =Calculs!$B$31 -> 0 | D22: Installation point de charge collectif.
B23: Économie carburant (récurrente) | C23: =Calculs!$B$35 -> 1636.88 | D23: Annuelle, vs essence/diesel actuel.
B24: Gain leasing social (récurrent) | C24: =Calculs!$B$36 -> 0 | D24: Annuel, vs LLD marché.
B25: ── LOGEMENT ──
B26: MaPrimeRénov' — PAC air/eau | C26: =Calculs!$B$41 -> 3000 | D26: Selon profil Anah.
B27: MaPrimeRénov' — PAC géothermique | C27: =Calculs!$B$42 -> 0 | D27: Selon profil Anah.
B28: MaPrimeRénov' — CET | C28: =Calculs!$B$43 -> 0 | D28: Selon profil Anah.
B29: CEE — Coup de pouce chauffage | C29: =Calculs!$B$44 -> 4000 | D29: Bonifié si sortie gaz/fioul.
B30: CEE — CET (BAR-TH-148) | C30: =Calculs!$B$45 -> 0 | D30: Si projet = CET seul.
B31: Bonus dépose cuve fioul | C31: =Calculs!$B$46 -> 0 | D31: Si chauffage actuel = fioul + PAC.
B32: MPR Parcours accompagné (Réno) | C32: =Calculs!$B$51 -> 0 | D32: Si rénovation d'ampleur.
B33: Bonus sortie passoire F/G | C33: =Calculs!$B$52 -> 0 | D33: Si DPE actuel F ou G + Réno.
B34: Économie chauffage PAC (récurrente) | C34: =Calculs!$B$60 -> 3988.2857 | D34: Annuelle.
B35: Économie CET (récurrente) | C35: =Calculs!$B$61 -> 0 | D35: Annuelle.
B36: Économie Réno ampleur (récurrente) | C36: =Calculs!$B$62 -> 0 | D36: Annuelle.
B37: ── SOLAIRE ──
B38: Prime à l'investissement PV | C38: =Calculs!$B$68 -> 0 | D38: Si projet PV ; € × kWc.
B39: Économie autoconsommation (récurrente) | C39: =Calculs!$B$70 -> 0 | D39: Annuelle.
B40: Revenu OA surplus PV (récurrent) | C40: =Calculs!$B$71 -> 0 | D40: Annuel ; tarif d'achat surplus.
B43: Profil Anah calculé
B44: Profil retenu : | C44: =Calculs!$B$9 -> violet | D44: Bleu / jaune / violet / rose — conditionne les barèmes.
B45: RFR / part : | C45: =Calculs!$B$12 -> 20000 | D45: Détermine la tranche prime VPE.
...

Sheet Étalement
A1: Bilan étalé sur 25 ans
A2: Cochez OUI/NON dans Saisies pour inclure chaque chantier. L'année de démarrage est paramétrable par chantier.
A4: Inclusion : | B4: PAC = | C4: =Saisies!$B$29 -> OUI | D4: Réno = | E4: =Saisies!$B$30 -> NON | F4: VE = | G4: =Saisies!$B$31 -> OUI | H4: PV = | I4: =Saisies!$B$32 -> NON
A5: Démarrage : | B5: PAC an | C5: =Saisies!$B$35 -> 1 | D5: Réno an | E5: =Saisies!$B$36 -> 1 | F5: VE an | G5: =Saisies!$B$37 -> 1 | H5: PV an | I5: =Saisies!$B$38 -> 1
A7: Bilan par solution (avant étalement)
A8: Solution | B8: Inclus ? | C8: Coût (€) | D8: Aides (€) | E8: Reste (€) | F8: Éco/an (€) | G8: Démarrage (an)
A9: PAC air/eau | B9: =Saisies!$B$29 -> OUI | C9: =IF(Saisies!$B$29="OUI",Hypothèses!$B$32,0) -> 14000 | D9: =IF(AND(Saisies!$B$29="OUI",Saisies!$B$10<>"loc"),MIN((INDEX(Hypothèses!$A$62:$D$65,Calculs!$B$10,2)+IF(OR(Saisies!$B$14="gaz",Saisies!$B$14="fioul"),INDEX(Hypothèses!$A$75:$E$78,Calculs!$B$10,2),INDEX(Hypothèses!$A$75:$E$78,Calculs!$B$10,3))+IF(Saisies!$B$14="fioul",INDEX(Hypothèses!$A$75:$E$78,Calculs!$B$10,5),0)),Hypothèses!$B$32*Hypothèses!$B$124),0) -> 7000 | E9: =MAX(0,C9-D9) -> 7000 | F9: =IF(AND(Saisies!$B$29="OUI",Saisies!$B$10<>"loc"),MAX(0,Calculs!$B$19-Calculs!$B$18/Hypothèses!$B$14*Hypothèses!$B$5),0) -> 3988.2857 | G9: =Saisies!$B$35 -> 1
A10: Rénovation d'ampleur | B10: =Saisies!$B$30 -> NON | C10: =IF(Saisies!$B$30="OUI",Hypothèses!$B$35,0) -> 0 | D10: =IF(AND(Saisies!$B$30="OUI",Saisies!$B$10<>"loc"),MIN(MIN(Hypothèses!$B$35,Calculs!$B$48)*Calculs!$B$49+IF(OR(Saisies!$B$13="F",Saisies!$B$13="G"),Hypothèses!$B$94,0),Hypothèses!$B$35*Hypothèses!$B$124),0) -> 0 | E10: =MAX(0,C10-D10) -> 0 | F10: =IF(AND(Saisies!$B$30="OUI",Saisies!$B$10<>"loc"),Calculs!$B$19*(1-Hypothèses!$B$96),0) -> 0 | G10: =Saisies!$B$36 -> 1
A11: VE neuf | B11: =Saisies!$B$31 -> OUI | C11: =IF(Saisies!$B$31="OUI",Hypothèses!$B$41+IF(Saisies!$B$23="oui",Hypothèses!$B$47,0),0) -> 10200 | D11: =IF(Saisies!$B$31="OUI",Calculs!$B$13+Hypothèses!$B$42+IF(AND(Saisies!$B$19="diesel",OR(Calculs!$B$9="bleu",Calculs!$B$9="jaune")),Hypothèses!$B$43,0)+IF(Saisies!$B$23="oui",MIN(Hypothèses!$B$47*Hypothèses!$B$48,Hypothèses!$B$49),0)+IF(Saisies!$B$23="copro",Hypothèses!$B$50,0),0) -> 4000 | E11: =MAX(0,C11-D11) -> 6200 | F11: =IF(AND(Saisies!$B$31="OUI",Saisies!$B$19<>"aucun"),Calculs!$B$22-Saisies!$B$20/100*Hypothèses!$B$18*IF(Saisies!$B$21="domicile",Hypothèses!$B$6,IF(Saisies!$B$21="urbain",0.25,0.3)),0) -> 1636.88 | G11: =Saisies!$B$37 -> 1
A12: Photovoltaïque | B12: =Saisies!$B$32 -> NON | C12: =IF(Saisies!$B$32="OUI",Hypothèses!$B$36,0) -> 0 | D12: =IF(Saisies!$B$32="OUI",Hypothèses!$B$57*IF(Hypothèses!$B$57<=3,Hypothèses!$B$53,Hypothèses!$B$54),0) -> 0 | E12: =MAX(0,C12-D12) -> 0 | F12: =IF(Saisies!$B$32="OUI",Hypothèses!$B$57*Hypothèses!$B$56*(Hypothèses!$B$58*Hypothèses!$B$5+(1-Hypothèses!$B$58)*Hypothèses!$B$55),0) -> 0 | G12: =Saisies!$B$38 -> 1
A13: TOTAL | C13: =SUM(C9:C12) -> 24200 | D13: =SUM(D9:D12) -> 11000 | E13: =SUM(E9:E12) -> 13200 | F13: =SUM(F9:F12) -> 5625.1657
A15: Bilan année par année
A16: Année | B16: Invest PAC | C16: Invest Réno | D16: Invest VE | E16: Invest PV | F16: Éco cumulée /an | G16: Coût scénario /an | H16: Coût actuel /an | I16: Cumul scénario | J16: Cumul « ne rien faire »
A17: 1 | B17: =IF(A17=G9,E9,0) -> 7000 | C17: =IF(A17=G10,E10,0) -> 0 | D17: =IF(A17=G11,E11,0) -> 6200 | E17: =IF(A17=G12,E12,0) -> 0 | F17: =IF(A17>=G9,F9,0)+IF(A17>=G10,F10,0)+IF(A17>=G11,F11,0)+IF(A17>=G12,F12,0) -> 5625.1657 | G17: =MAX(0,Calculs!$B$23-F17) -> 7172.8343 | H17: =Calculs!$B$23 -> 12798 | I17: =B17+C17+D17+E17+G17 -> 20372.834 | J17: =H17 -> 12798
A18: 2 | B18: =IF(A18=G9,E9,0) -> 0 | C18: =IF(A18=G10,E10,0) -> 0 | D18: =IF(A18=G11,E11,0) -> 0 | E18: =IF(A18=G12,E12,0) -> 0 | F18: =IF(A18>=G9,F9,0)+IF(A18>=G10,F10,0)+IF(A18>=G11,F11,0)+IF(A18>=G12,F12,0) -> 5625.1657 | G18: =MAX(0,Calculs!$B$23-F18) -> 7172.8343 | H18: =Calculs!$B$23 -> 12798 | I18: =I17+B18+C18+D18+E18+G18 -> 27545.669 | J18: =J17+H18 -> 25596
A19: 3 | B19: =IF(A19=G9,E9,0) -> 0 | C19: =IF(A19=G10,E10,0) -> 0 | D19: =IF(A19=G11,E11,0) -> 0 | E19: =IF(A19=G12,E12,0) -> 0 | F19: =IF(A19>=G9,F9,0)+IF(A19>=G10,F10,0)+IF(A19>=G11,F11,0)+IF(A19>=G12,F12,0) -> 5625.1657 | G19: =MAX(0,Calculs!$B$23-F19) -> 7172.8343 | H19: =Calculs!$B$23 -> 12798 | I19: =I18+B19+C19+D19+E19+G19 -> 34718.503 | J19: =J18+H19 -> 38394
A20: 4 | B20: =IF(A20=G9,E9,0) -> 0 | C20: =IF(A20=G10,E10,0) -> 0 | D20: =IF(A20=G11,E11,0) -> 0 | E20: =IF(A20=G12,E12,0) -> 0 | F20: =IF(A20>=G9,F9,0)+IF(A20>=G10,F10,0)+IF(A20>=G11,F11,0)+IF(A20>=G12,F12,0) -> 5625.1657 | G20: =MAX(0,Calculs!$B$23-F20) -> 7172.8343 | H20: =Calculs!$B$23 -> 12798 | I20: =I19+B20+C20+D20+E20+G20 -> 41891.337 | J20: =J19+H20 -> 51192
A21: 5 | B21: =IF(A21=G9,E9,0) -> 0 | C21: =IF(A21=G10,E10,0) -> 0 | D21: =IF(A21=G11,E11,0) -> 0 | E21: =IF(A21=G12,E12,0) -> 0 | F21: =IF(A21>=G9,F9,0)+IF(A21>=G10,F10,0)+IF(A21>=G11,F11,0)+IF(A21>=G12,F12,0) -> 5625.1657 | G21: =MAX(0,Calculs!$B$23-F21) -> 7172.8343 | H21: =Calculs!$B$23 -> 12798 | I21: =I20+B21+C21+D21+E21+G21 -> 49064.171 | J21: =J20+H21 -> 63990
A22: 6 | B22: =IF(A22=G9,E9,0) -> 0 | C22: =IF(A22=G10,E10,0) -> 0 | D22: =IF(A22=G11,E11,0) -> 0 | E22: =IF(A22=G12,E12,0) -> 0 | F22: =IF(A22>=G9,F9,0)+IF(A22>=G10,F10,0)+IF(A22>=G11,F11,0)+IF(A22>=G12,F12,0) -> 5625.1657 | G22: =MAX(0,Calculs!$B$23-F22) -> 7172.8343 | H22: =Calculs!$B$23 -> 12798 | I22: =I21+B22+C22+D22+E22+G22 -> 56237.006 | J22: =J21+H22 -> 76788
A23: 7 | B23: =IF(A23=G9,E9,0) -> 0 | C23: =IF(A23=G10,E10,0) -> 0 | D23: =IF(A23=G11,E11,0) -> 0 | E23: =IF(A23=G12,E12,0) -> 0 | F23: =IF(A23>=G9,F9,0)+IF(A23>=G10,F10,0)+IF(A23>=G11,F11,0)+IF(A23>=G12,F12,0) -> 5625.1657 | G23: =MAX(0,Calculs!$B$23-F23) -> 7172.8343 | H23: =Calculs!$B$23 -> 12798 | I23: =I22+B23+C23+D23+E23+G23 -> 63409.84 | J23: =J22+H23 -> 89586
A24: 8 | B24: =IF(A24=G9,E9,0) -> 0 | C24: =IF(A24=G10,E10,0) -> 0 | D24: =IF(A24=G11,E11,0) -> 0 | E24: =IF(A24=G12,E12,0) -> 0 | F24: =IF(A24>=G9,F9,0)+IF(A24>=G10,F10,0)+IF(A24>=G11,F11,0)+IF(A24>=G12,F12,0) -> 5625.1657 | G24: =MAX(0,Calculs!$B$23-F24) -> 7172.8343 | H24: =Calculs!$B$23 -> 12798 | I24: =I23+B24+C24+D24+E24+G24 -> 70582.674 | J24: =J23+H24 -> 102384
A25: 9 | B25: =IF(A25=G9,E9,0) -> 0 | C25: =IF(A25=G10,E10,0) -> 0 | D25: =IF(A25=G11,E11,0) -> 0 | E25: =IF(A25=G12,E12,0) -> 0 | F25: =IF(A25>=G9,F9,0)+IF(A25>=G10,F10,0)+IF(A25>=G11,F11,0)+IF(A25>=G12,F12,0) -> 5625.1657 | G25: =MAX(0,Calculs!$B$23-F25) -> 7172.8343 | H25: =Calculs!$B$23 -> 12798 | I25: =I24+B25+C25+D25+E25+G25 -> 77755.509 | J25: =J24+H25 -> 115182
A26: 10 | B26: =IF(A26=G9,E9,0) -> 0 | C26: =IF(A26=G10,E10,0) -> 0 | D26: =IF(A26=G11,E11,0) -> 0 | E26: =IF(A26=G12,E12,0) -> 0 | F26: =IF(A26>=G9,F9,0)+IF(A26>=G10,F10,0)+IF(A26>=G11,F11,0)+IF(A26>=G12,F12,0) -> 5625.1657 | G26: =MAX(0,Calculs!$B$23-F26) -> 7172.8343 | H26: =Calculs!$B$23 -> 12798 | I26: =I25+B26+C26+D26+E26+G26 -> 84928.343 | J26: =J25+H26 -> 127980
A27: 11 | B27: =IF(A27=G9,E9,0) -> 0 | C27: =IF(A27=G10,E10,0) -> 0 | D27: =IF(A27=G11,E11,0) -> 0 | E27: =IF(A27=G12,E12,0) -> 0 | F27: =IF(A27>=G9,F9,0)+IF(A27>=G10,F10,0)+IF(A27>=G11,F11,0)+IF(A27>=G12,F12,0) -> 5625.1657 | G27: =MAX(0,Calculs!$B$23-F27) -> 7172.8343 | H27: =Calculs!$B$23 -> 12798 | I27: =I26+B27+C27+D27+E27+G27 -> 92101.177 | J27: =J26+H27 -> 140778
A28: 12 | B28: =IF(A28=G9,E9,0) -> 0 | C28: =IF(A28=G10,E10,0) -> 0 | D28: =IF(A28=G11,E11,0) -> 0 | E28: =IF(A28=G12,E12,0) -> 0 | F28: =IF(A28>=G9,F9,0)+IF(A28>=G10,F10,0)+IF(A28>=G11,F11,0)+IF(A28>=G12,F12,0) -> 5625.1657 | G28: =MAX(0,Calculs!$B$23-F28) -> 7172.8343 | H28: =Calculs!$B$23 -> 12798 | I28: =I27+B28+C28+D28+E28+G28 -> 99274.011 | J28: =J27+H28 -> 153576
A29: 13 | B29: =IF(A29=G9,E9,0) -> 0 | C29: =IF(A29=G10,E10,0) -> 0 | D29: =IF(A29=G11,E11,0) -> 0 | E29: =IF(A29=G12,E12,0) -> 0 | F29: =IF(A29>=G9,F9,0)+IF(A29>=G10,F10,0)+IF(A29>=G11,F11,0)+IF(A29>=G12,F12,0) -> 5625.1657 | G29: =MAX(0,Calculs!$B$23-F29) -> 7172.8343 | H29: =Calculs!$B$23 -> 12798 | I29: =I28+B29+C29+D29+E29+G29 -> 106446.85 | J29: =J28+H29 -> 166374
A30: 14 | B30: =IF(A30=G9,E9,0) -> 0 | C30: =IF(A30=G10,E10,0) -> 0 | D30: =IF(A30=G11,E11,0) -> 0 | E30: =IF(A30=G12,E12,0) -> 0 | F30: =IF(A30>=G9,F9,0)+IF(A30>=G10,F10,0)+IF(A30>=G11,F11,0)+IF(A30>=G12,F12,0) -> 5625.1657 | G30: =MAX(0,Calculs!$B$23-F30) -> 7172.8343 | H30: =Calculs!$B$23 -> 12798 | I30: =I29+B30+C30+D30+E30+G30 -> 113619.68 | J30: =J29+H30 -> 179172
A31: 15 | B31: =IF(A31=G9,E9,0) -> 0 | C31: =IF(A31=G10,E10,0) -> 0 | D31: =IF(A31=G11,E11,0) -> 0 | E31: =IF(A31=G12,E12,0) -> 0 | F31: =IF(A31>=G9,F9,0)+IF(A31>=G10,F10,0)+IF(A31>=G11,F11,0)+IF(A31>=G12,F12,0) -> 5625.1657 | G31: =MAX(0,Calculs!$B$23-F31) -> 7172.8343 | H31: =Calculs!$B$23 -> 12798 | I31: =I30+B31+C31+D31+E31+G31 -> 120792.51 | J31: =J30+H31 -> 191970
A32: 16 | B32: =IF(A32=G9,E9,0) -> 0 | C32: =IF(A32=G10,E10,0) -> 0 | D32: =IF(A32=G11,E11,0) -> 0 | E32: =IF(A32=G12,E12,0) -> 0 | F32: =IF(A32>=G9,F9,0)+IF(A32>=G10,F10,0)+IF(A32>=G11,F11,0)+IF(A32>=G12,F12,0) -> 5625.1657 | G32: =MAX(0,Calculs!$B$23-F32) -> 7172.8343 | H32: =Calculs!$B$23 -> 12798 | I32: =I31+B32+C32+D32+E32+G32 -> 127965.35 | J32: =J31+H32 -> 204768
A33: 17 | B33: =IF(A33=G9,E9,0) -> 0 | C33: =IF(A33=G10,E10,0) -> 0 | D33: =IF(A33=G11,E11,0) -> 0 | E33: =IF(A33=G12,E12,0) -> 0 | F33: =IF(A33>=G9,F9,0)+IF(A33>=G10,F10,0)+IF(A33>=G11,F11,0)+IF(A33>=G12,F12,0) -> 5625.1657 | G33: =MAX(0,Calculs!$B$23-F33) -> 7172.8343 | H33: =Calculs!$B$23 -> 12798 | I33: =I32+B33+C33+D33+E33+G33 -> 135138.18 | J33: =J32+H33 -> 217566
A34: 18 | B34: =IF(A34=G9,E9,0) -> 0 | C34: =IF(A34=G10,E10,0) -> 0 | D34: =IF(A34=G11,E11,0) -> 0 | E34: =IF(A34=G12,E12,0) -> 0 | F34: =IF(A34>=G9,F9,0)+IF(A34>=G10,F10,0)+IF(A34>=G11,F11,0)+IF(A34>=G12,F12,0) -> 5625.1657 | G34: =MAX(0,Calculs!$B$23-F34) -> 7172.8343 | H34: =Calculs!$B$23 -> 12798 | I34: =I33+B34+C34+D34+E34+G34 -> 142311.02 | J34: =J33+H34 -> 230364
A35: 19 | B35: =IF(A35=G9,E9,0) -> 0 | C35: =IF(A35=G10,E10,0) -> 0 | D35: =IF(A35=G11,E11,0) -> 0 | E35: =IF(A35=G12,E12,0) -> 0 | F35: =IF(A35>=G9,F9,0)+IF(A35>=G10,F10,0)+IF(A35>=G11,F11,0)+IF(A35>=G12,F12,0) -> 5625.1657 | G35: =MAX(0,Calculs!$B$23-F35) -> 7172.8343 | H35: =Calculs!$B$23 -> 12798 | I35: =I34+B35+C35+D35+E35+G35 -> 149483.85 | J35: =J34+H35 -> 243162
A36: 20 | B36: =IF(A36=G9,E9,0) -> 0 | C36: =IF(A36=G10,E10,0) -> 0 | D36: =IF(A36=G11,E11,0) -> 0 | E36: =IF(A36=G12,E12,0) -> 0 | F36: =IF(A36>=G9,F9,0)+IF(A36>=G10,F10,0)+IF(A36>=G11,F11,0)+IF(A36>=G12,F12,0) -> 5625.1657 | G36: =MAX(0,Calculs!$B$23-F36) -> 7172.8343 | H36: =Calculs!$B$23 -> 12798 | I36: =I35+B36+C36+D36+E36+G36 -> 156656.69 | J36: =J35+H36 -> 255960
A37: 21 | B37: =IF(A37=G9,E9,0) -> 0 | C37: =IF(A37=G10,E10,0) -> 0 | D37: =IF(A37=G11,E11,0) -> 0 | E37: =IF(A37=G12,E12,0) -> 0 | F37: =IF(A37>=G9,F9,0)+IF(A37>=G10,F10,0)+IF(A37>=G11,F11,0)+IF(A37>=G12,F12,0) -> 5625.1657 | G37: =MAX(0,Calculs!$B$23-F37) -> 7172.8343 | H37: =Calculs!$B$23 -> 12798 | I37: =I36+B37+C37+D37+E37+G37 -> 163829.52 | J37: =J36+H37 -> 268758
A38: 22 | B38: =IF(A38=G9,E9,0) -> 0 | C38: =IF(A38=G10,E10,0) -> 0 | D38: =IF(A38=G11,E11,0) -> 0 | E38: =IF(A38=G12,E12,0) -> 0 | F38: =IF(A38>=G9,F9,0)+IF(A38>=G10,F10,0)+IF(A38>=G11,F11,0)+IF(A38>=G12,F12,0) -> 5625.1657 | G38: =MAX(0,Calculs!$B$23-F38) -> 7172.8343 | H38: =Calculs!$B$23 -> 12798 | I38: =I37+B38+C38+D38+E38+G38 -> 171002.35 | J38: =J37+H38 -> 281556
A39: 23 | B39: =IF(A39=G9,E9,0) -> 0 | C39: =IF(A39=G10,E10,0) -> 0 | D39: =IF(A39=G11,E11,0) -> 0 | E39: =IF(A39=G12,E12,0) -> 0 | F39: =IF(A39>=G9,F9,0)+IF(A39>=G10,F10,0)+IF(A39>=G11,F11,0)+IF(A39>=G12,F12,0) -> 5625.1657 | G39: =MAX(0,Calculs!$B$23-F39) -> 7172.8343 | H39: =Calculs!$B$23 -> 12798 | I39: =I38+B39+C39+D39+E39+G39 -> 178175.19 | J39: =J38+H39 -> 294354
A40: 24 | B40: =IF(A40=G9,E9,0) -> 0 | C40: =IF(A40=G10,E10,0) -> 0 | D40: =IF(A40=G11,E11,0) -> 0 | E40: =IF(A40=G12,E12,0) -> 0 | F40: =IF(A40>=G9,F9,0)+IF(A40>=G10,F10,0)+IF(A40>=G11,F11,0)+IF(A40>=G12,F12,0) -> 5625.1657 | G40: =MAX(0,Calculs!$B$23-F40) -> 7172.8343 | H40: =Calculs!$B$23 -> 12798 | I40: =I39+B40+C40+D40+E40+G40 -> 185348.02 | J40: =J39+H40 -> 307152
A41: 25 | B41: =IF(A41=G9,E9,0) -> 0 | C41: =IF(A41=G10,E10,0) -> 0 | D41: =IF(A41=G11,E11,0) -> 0 | E41: =IF(A41=G12,E12,0) -> 0 | F41: =IF(A41>=G9,F9,0)+IF(A41>=G10,F10,0)+IF(A41>=G11,F11,0)+IF(A41>=G12,F12,0) -> 5625.1657 | G41: =MAX(0,Calculs!$B$23-F41) -> 7172.8343 | H41: =Calculs!$B$23 -> 12798 | I41: =I40+B41+C41+D41+E41+G41 -> 192520.86 | J41: =J40+H41 -> 319950
A43: Synthèse
A44: Cumul scénario sur horizon | B44: =INDEX(I17:I41,Saisies!$B$26) -> 156656.69
...
