Workbook

Sheet Saisies
A1: Saisies — votre projet PAC
A2: Cellules bleues à renseigner. Calculs et résultats se mettent à jour automatiquement.
A4: Mon logement
A5: Surface chauffée (m²) | B5: 120 | C5: Entre 40 et 250 m².
A6: Zone climatique | B6: H2 | C6: H1 (Nord-est, froid) · H2 (Ouest/Centre/Sud-Ouest) · H3 (Méditerranée).
A7: État de l'isolation | B7: moyen | C7: passoire (DPE F-G) · moyen (D-E) · bon (B-C).
A8: Chauffage actuel | B8: gaz | C8: fioul · gaz · propane · elec.
A10: Mon projet PAC
A11: Type de PAC | B11: aireau | C11: aireau · geo · airair (air/air non éligible MPR).
A12: Profil de revenus (plafonds Anah) | B12: violet | C12: bleu (très mod.) · jaune (modeste) · violet (interm.) · rose (supérieur).
A14: Override facture réelle (optionnel — laisser 0 pour ignorer)
A15: Montant facture annuelle TTC (€) | B15: 0 | C15: Si > 0, calibre directement sur ce montant (prioritaire).
A16: Consommation annuelle (unité selon énergie) | B16: 0 | C16: Si > 0 et montant = 0, calibre sur cette conso. Unité : voir Hypothèses (litres / kWh / kg).

Sheet Hypothèses
A1: Hypothèses — Simulateur Pompe à chaleur 2026
A2: Cellules bleues = modifiables. Le reste du classeur recalcule automatiquement.
A4: Énergies : prix, rendement chaudière, conversion d'unité
A5: Code énergie | B5: Prix (€/kWh) | C5: Rendement | D5: kWh / unité | E5: Unité de la facture
A6: fioul | B6: 0.11 | C6: 0.8 | D6: 10 | E6: litres/an | F6: Prix TTC mai 2026 (CRE/CGDD). Rendements de la chaudière en place.
A7: gaz | B7: 0.126 | C7: 0.95 | D7: 1 | E7: kWh/an
A8: propane | B8: 0.16 | C8: 0.9 | D8: 13.8 | E8: kg/an
A9: elec | B9: 0.194 | C9: 1 | D9: 1 | E9: kWh/an
A11: SCOP saisonnier des pompes à chaleur
A12: Code PAC | B12: SCOP | C12: Coût install (€)
A13: aireau | B13: 3.8 | C13: 14000 | F13: SCOP médian observé en France 2024-2025. Coût TTC clé en main médian (FNCH).
A14: geo | B14: 4.5 | C14: 28000
A15: airair | B15: 3.5 | C15: 9000
A17: Besoin de chauffage par zone climatique (kWh utiles/m²/an)
A18: Zone | B18: kWh/m²/an
A19: H1 | B19: 130 | F19: Hyp. logement DPE D-E ; ajusté par le facteur isolation.
A20: H2 | B20: 110
A21: H3 | B21: 90
A23: Facteur isolation (multiplicateur du besoin)
A24: Code isolation | B24: Facteur
A25: passoire | B25: 1.5 | F25: passoire = DPE F-G (× 1,5) ; moyen = D-E (× 1,0) ; bon = B-C (× 0,65).
A26: moyen | B26: 1
A27: bon | B27: 0.65
A29: MaPrimeRénov' parcours par geste (€) — PAC × profil
A30: Code PAC / Profil | B30: bleu (très mod.) | C30: jaune (modeste) | D30: violet (interm.) | E30: rose (supérieur)
A31: aireau | B31: 5000 | C31: 4000 | D31: 3000 | E31: 0 | F31: Source : Anah — MPR parcours par geste 2026. Air/air non éligible.
A32: geo | B32: 11000 | C32: 9000 | D32: 6000 | E32: 0
A33: airair | B33: 0 | C33: 0 | D33: 0 | E33: 0
A35: Plafonds MaPrimeRénov' (€ de travaux pris en compte)
A36: Plafond travaux PAC air/eau | B36: 12000 | F36: Anah
A37: Plafond travaux PAC géothermique | B37: 20000 | F37: Anah
A38: Plafond travaux PAC air/air | B38: 0 | F38: Air/air non éligible
A40: CEE Coup de pouce chauffage (€) — par profil
A41: Type / Profil | B41: bleu | C41: jaune | D41: violet | E41: rose
A42: Bonifié | B42: 5000 | C42: 5000 | D42: 4000 | E42: 2500 | F42: Bonifié = remplacement chaudière fioul/gaz/propane → PAC air/eau ou géo.
A43: Standard | B43: 1000 | C43: 1000 | D43: 800 | E43: 500
A45: Bonus dépose cuve fioul (€) — par profil
A46: Profil | B46: Montant
A47: bleu | B47: 1200 | F47: Uniquement si énergie actuelle = fioul ET PAC ≠ air/air.
A48: jaune | B48: 800
...

Sheet Calculs
A1: Calculs intermédiaires
A2: Formules reproduisant le JS du simulateur PAC. Ne modifier que Saisies / Hypothèses.
A4: 1. Lookups depuis Hypothèses
A5: Prix énergie actuelle (€/kWh) | B5: =VLOOKUP(Saisies!$B$8,Hypothèses!$A$6:$E$9,2,FALSE()) -> 0.126 | C5: Lookup dans la table énergies.
A6: Rendement chaudière actuelle | B6: =VLOOKUP(Saisies!$B$8,Hypothèses!$A$6:$E$9,3,FALSE()) -> 0.95 | C6: Rendement combustion.
A7: kWh par unité (conversion facture) | B7: =VLOOKUP(Saisies!$B$8,Hypothèses!$A$6:$E$9,4,FALSE()) -> 1 | C7: 1 L fioul = 10 kWh ; 1 kg propane = 13,8 kWh ; etc.
A8: Prix électricité (€/kWh, alimentation PAC) | B8: =VLOOKUP("elec",Hypothèses!$A$6:$E$9,2,FALSE()) -> 0.194 | C8: La PAC consomme de l'électricité.
A9: SCOP de la PAC choisie | B9: =VLOOKUP(Saisies!$B$11,Hypothèses!$A$13:$C$15,2,FALSE()) -> 3.8 | C9: Coefficient de performance saisonnier.
A10: Coût d'installation PAC (€) | B10: =VLOOKUP(Saisies!$B$11,Hypothèses!$A$13:$C$15,3,FALSE()) -> 14000 | C10: TTC clé en main.
A11: Besoin base zone (kWh/m²/an) | B11: =VLOOKUP(Saisies!$B$6,Hypothèses!$A$19:$B$21,2,FALSE()) -> 110 | C11: Selon H1/H2/H3.
A12: Facteur isolation | B12: =VLOOKUP(Saisies!$B$7,Hypothèses!$A$25:$B$27,2,FALSE()) -> 1 | C12: Multiplicateur du besoin.
A13: Index PAC (1=aireau, 2=geo, 3=airair) | B13: =MATCH(Saisies!$B$11,{"aireau";"geo";"airair"},0) -> 1 | C13: Sert aux lookups MPR.
A14: Index profil (1=bleu .. 4=rose) | B14: =MATCH(Saisies!$B$12,{"bleu";"jaune";"violet";"rose"},0) -> 3 | C14: Sert aux lookups MPR/CEE.
A16: 2. Besoin utile (kWh/an) — avec override facture
A17: Override facture actif ? (1 = oui) | B17: =IF(OR(Saisies!$B$15>0,Saisies!$B$16>0),1,0) -> 0 | C17: Activé dès qu'au moins un override est renseigné.
A18: Conso finale via facture (€) (si montant fourni) | B18: =IF(Saisies!$B$15>0,Saisies!$B$15/Calculs!$B$5,0) -> 0 | C18: Montant ÷ prix énergie = kWh consommés.
A19: Conso finale via facture (kWh) (si conso fournie) | B19: =IF(AND(Saisies!$B$15=0,Saisies!$B$16>0),Saisies!$B$16*Calculs!$B$7,0) -> 0 | C19: Conso brute × kWh/unité.
A20: Besoin utile via override (kWh/an) | B20: =IF(Calculs!$B$17=1,(Calculs!$B$18+Calculs!$B$19)*Calculs!$B$6,0) -> 0 | C20: Énergie finale × rendement de la chaudière = énergie utile (chaleur produite).
A21: Besoin utile via surface (kWh/an) | B21: =Saisies!$B$5*Calculs!$B$11*Calculs!$B$12 -> 13200 | C21: Surface × besoin/m² × facteur isolation.
A22: BESOIN UTILE RETENU (kWh/an) | B22: =IF(Calculs!$B$17=1,Calculs!$B$20,Calculs!$B$21) -> 13200 | C22: Override prioritaire si actif.
A24: 3. Coûts annuels par solution (€/an)
A25: Conso fioul (kWh/an) | B25: =Calculs!$B$22/VLOOKUP("fioul",Hypothèses!$A$6:$E$9,3,FALSE()) -> 16500
A26: Conso gaz (kWh/an) | B26: =Calculs!$B$22/VLOOKUP("gaz",Hypothèses!$A$6:$E$9,3,FALSE()) -> 13894.737
A27: Conso propane (kWh/an) | B27: =Calculs!$B$22/VLOOKUP("propane",Hypothèses!$A$6:$E$9,3,FALSE()) -> 14666.667
A28: Conso élec direct (kWh/an) | B28: =Calculs!$B$22/VLOOKUP("elec",Hypothèses!$A$6:$E$9,3,FALSE()) -> 13200
A29: Conso PAC (kWh/an élec) | B29: =Calculs!$B$22/Calculs!$B$9 -> 3473.6842 | C29: Besoin utile ÷ SCOP.
A30: Coût fioul /an (€) | B30: =Calculs!$B$22/VLOOKUP("fioul",Hypothèses!$A$6:$E$9,3,FALSE())*VLOOKUP("fioul",Hypothèses!$A$6:$E$9,2,FALSE()) -> 1815
A31: Coût gaz /an (€) | B31: =Calculs!$B$22/VLOOKUP("gaz",Hypothèses!$A$6:$E$9,3,FALSE())*VLOOKUP("gaz",Hypothèses!$A$6:$E$9,2,FALSE()) -> 1750.7368
A32: Coût propane /an (€) | B32: =Calculs!$B$22/VLOOKUP("propane",Hypothèses!$A$6:$E$9,3,FALSE())*VLOOKUP("propane",Hypothèses!$A$6:$E$9,2,FALSE()) -> 2346.6667
A33: Coût élec direct /an (€) | B33: =Calculs!$B$22/VLOOKUP("elec",Hypothèses!$A$6:$E$9,3,FALSE())*VLOOKUP("elec",Hypothèses!$A$6:$E$9,2,FALSE()) -> 2560.8
A34: Coût PAC /an (€) | B34: =Calculs!$B$29*Calculs!$B$8 -> 673.89474 | C34: Conso PAC × prix élec.
A35: Coût ÉNERGIE ACTUELLE /an (€) | B35: =IF(Saisies!$B$15>0,Saisies!$B$15,IF(Saisies!$B$8="fioul",Calculs!$B$30,IF(Saisies!$B$8="gaz",Calculs!$B$31,IF(Saisies!$B$8="propane",Calculs!$B$32,Calculs!$B$33)))) -> 1750.7368 | C35: Montant direct si saisi, sinon coût calculé selon énergie.
A37: 4. Aides mobilisables
A38: Remplace énergie fossile ? | B38: =IF(OR(Saisies!$B$8="fioul",Saisies!$B$8="gaz",Saisies!$B$8="propane"),1,0) -> 1 | C38: 1 = oui (déclenche le bonifié si PAC ≠ air/air).
A39: Éligible Coup de pouce bonifié ? | B39: =IF(AND(Calculs!$B$38=1,Saisies!$B$11<>"airair"),1,0) -> 1
A40: MaPrimeRénov' (€) | B40: =INDEX(Hypothèses!$A$31:$E$33,Calculs!$B$13,Calculs!$B$14+1) -> 3000 | C40: Lookup table MPR : pac × profil.
A41: CEE bonifié (€) — lookup | B41: =INDEX(Hypothèses!$A$42:$E$43,1,Calculs!$B$14+1) -> 4000 | C41: Coup de pouce bonifié pour le profil.
A42: CEE standard (€) — lookup | B42: =INDEX(Hypothèses!$A$42:$E$43,2,Calculs!$B$14+1) -> 800
A43: CEE retenu (€) | B43: =IF(Calculs!$B$39=1,Calculs!$B$41,Calculs!$B$42) -> 4000 | C43: Bonifié si remplacement fossile + PAC ≠ air/air ; standard sinon.
A44: Bonus dépose fioul brut (€) — lookup | B44: =INDEX(Hypothèses!$A$47:$B$50,Calculs!$B$14,2) -> 400 | C44: Montant selon profil.
...

Sheet Résultats
B1: Résultats — synthèse PAC
B2: Tous les chiffres se mettent à jour à chaque modification des Saisies ou des Hypothèses.
B4: Indicateurs clés
B5: Coût d'installation | C5: =Calculs!$B$10 -> 14000 | D5: TTC clé en main (pose + matériel).
B6: Aides publiques mobilisables | C6: =Calculs!$B$48 -> 7000 | D6: MaPrimeRénov' + CEE + bonus dépose, plafonné à 90 % du coût.
B7: % du projet financé par l'État | C7: =IF(Calculs!$B$10>0,Calculs!$B$48/Calculs!$B$10,0) -> 0.5 | D7: Aides ÷ coût install.
B8: Reste à votre charge | C8: =Calculs!$B$49 -> 7000 | D8: Coût − aides.
B9: Économie annuelle (vs chauffage actuel) | C9: =Calculs!$B$50 -> 1076.8421 | D9: Positif = gain, négatif = surcoût.
B12: Détail des dispositifs
B13: Dispositif | C13: Montant | D13: Conditions
B14: MaPrimeRénov' | C14: =Calculs!$B$40 -> 3000 | D14: Selon PAC × profil. Air/air = 0 €.
B15: CEE Coup de pouce chauffage | C15: =Calculs!$B$43 -> 4000 | D15: Bonifié si remplacement fossile + PAC ≠ air/air.
B16: Bonus dépose cuve fioul | C16: =Calculs!$B$45 -> 0 | D16: Si chauffage actuel = fioul + PAC eau.
B17: Aides brutes (avant plafond) | C17: =Calculs!$B$46 -> 7000 | D17: Somme directe.
B18: Plafond cumul (90 % coût) | C18: =Calculs!$B$47 -> 12600 | D18: Garde-fou réglementaire.
B19: TOTAL aides retenues | C19: =Calculs!$B$48 -> 7000 | D19: Soit MIN(brutes ; plafond).
B21: Détail du besoin & du coût actuel
B22: Besoin utile retenu (kWh/an) | C22: =Calculs!$B$22 -> 13200 | D22: Surface × besoin/m² × facteur isolation OU calibré sur facture.
B23: Coût énergie actuelle (€/an) | C23: =Calculs!$B$35 -> 1750.7368
B24: Coût PAC (€/an) | C24: =Calculs!$B$34 -> 673.89474 | D24: Conso PAC × prix élec.
B25: Économies annuelles (€/an) | C25: =Calculs!$B$50 -> 1076.8421 | D25: Coût actuel − coût PAC.

Sheet Amortissement
B1: Amortissement sur 15 ans + comparaison TCO
B2: Cumul net annuel (économies inflées à 3 %/an) + coût total cumulé par solution.
B4: Évolution année par année
B5: Année | C5: Économie/an inflée | D5: Cumul net | E5: Cumul vs coût install | F5: Statut
B6: 0 | C6: 0 | D6: =-Calculs!$B$49 -> -7000 | E6: =IF(D6>=0,"Équilibré","À amortir") -> À amortir
B7: 1 | C7: =Calculs!$B$50*(1+Hypothèses!$B$54)^(1-1) -> 1076.8421 | D7: =D6+C7 -> -5923.1579 | E7: =IF(D7>=0,"Équilibré","À amortir") -> À amortir
B8: 2 | C8: =Calculs!$B$50*(1+Hypothèses!$B$54)^(2-1) -> 1109.1474 | D8: =D7+C8 -> -4814.0105 | E8: =IF(D8>=0,"Équilibré","À amortir") -> À amortir
B9: 3 | C9: =Calculs!$B$50*(1+Hypothèses!$B$54)^(3-1) -> 1142.4218 | D9: =D8+C9 -> -3671.5887 | E9: =IF(D9>=0,"Équilibré","À amortir") -> À amortir
B10: 4 | C10: =Calculs!$B$50*(1+Hypothèses!$B$54)^(4-1) -> 1176.6944 | D10: =D9+C10 -> -2494.8943 | E10: =IF(D10>=0,"Équilibré","À amortir") -> À amortir
B11: 5 | C11: =Calculs!$B$50*(1+Hypothèses!$B$54)^(5-1) -> 1211.9953 | D11: =D10+C11 -> -1282.899 | E11: =IF(D11>=0,"Équilibré","À amortir") -> À amortir
B12: 6 | C12: =Calculs!$B$50*(1+Hypothèses!$B$54)^(6-1) -> 1248.3551 | D12: =D11+C12 -> -34.543882 | E12: =IF(D12>=0,"Équilibré","À amortir") -> À amortir
B13: 7 | C13: =Calculs!$B$50*(1+Hypothèses!$B$54)^(7-1) -> 1285.8058 | D13: =D12+C13 -> 1251.2619 | E13: =IF(D13>=0,"Équilibré","À amortir") -> Équilibré
B14: 8 | C14: =Calculs!$B$50*(1+Hypothèses!$B$54)^(8-1) -> 1324.38 | D14: =D13+C14 -> 2575.6419 | E14: =IF(D14>=0,"Équilibré","À amortir") -> Équilibré
B15: 9 | C15: =Calculs!$B$50*(1+Hypothèses!$B$54)^(9-1) -> 1364.1114 | D15: =D14+C15 -> 3939.7532 | E15: =IF(D15>=0,"Équilibré","À amortir") -> Équilibré
B16: 10 | C16: =Calculs!$B$50*(1+Hypothèses!$B$54)^(10-1) -> 1405.0347 | D16: =D15+C16 -> 5344.7879 | E16: =IF(D16>=0,"Équilibré","À amortir") -> Équilibré
B17: 11 | C17: =Calculs!$B$50*(1+Hypothèses!$B$54)^(11-1) -> 1447.1857 | D17: =D16+C17 -> 6791.9737 | E17: =IF(D17>=0,"Équilibré","À amortir") -> Équilibré
B18: 12 | C18: =Calculs!$B$50*(1+Hypothèses!$B$54)^(12-1) -> 1490.6013 | D18: =D17+C18 -> 8282.575 | E18: =IF(D18>=0,"Équilibré","À amortir") -> Équilibré
B19: 13 | C19: =Calculs!$B$50*(1+Hypothèses!$B$54)^(13-1) -> 1535.3194 | D19: =D18+C19 -> 9817.8943 | E19: =IF(D19>=0,"Équilibré","À amortir") -> Équilibré
B20: 14 | C20: =Calculs!$B$50*(1+Hypothèses!$B$54)^(14-1) -> 1581.3789 | D20: =D19+C20 -> 11399.273 | E20: =IF(D20>=0,"Équilibré","À amortir") -> Équilibré
B21: 15 | C21: =Calculs!$B$50*(1+Hypothèses!$B$54)^(15-1) -> 1628.8203 | D21: =D20+C21 -> 13028.094 | E21: =IF(D21>=0,"Équilibré","À amortir") -> Équilibré
B23: Point d'équilibre
B24: Position MATCH (1-indexed) | C24: =IFERROR(MATCH(0,D6:D21,1),0) -> 7 | F24: Dernière année où cumul ≤ 0.
B25: Index année avant équilibre (0-indexed) | C25: =C24-1 -> 6
B26: Cumul à cet index (€) | C26: =INDEX(D6:D21,C24) -> -34.543882
B27: Cumul année suivante (€) | C27: =IFERROR(INDEX(D6:D21,C24+1),INDEX(D6:D21,C24)) -> 1251.2619
B28: POINT D'ÉQUILIBRE (années) | C28: =IF(Calculs!$B$50<=0,"Jamais (surcoût)",IF(INDEX(D6:D21,16)<0,"Au-delà de 15 ans",(C24-1)+IF(C27-C26<>0,-C26/(C27-C26),0))) -> 6.0268656 | F28: Interpolation linéaire entre les deux années encadrant le 0.
B30: TCO sur 15 ans — comparaison
B31: Solution | C31: Coût install (€) | D31: Coût annuel (€) | E31: TCO 15 ans (€)
B32: Fioul (remplacement chaudière) | C32: =Hypothèses!$B$58 -> 8000 | D32: =Calculs!$B$30 -> 1815 | E32: =C32+D32*(((1+Hypothèses!$B$54)^Hypothèses!$B$53-1)/Hypothèses!$B$54) -> 41757.029
B33: Gaz (chaudière condensation) | C33: =Hypothèses!$B$59 -> 5000 | D33: =Calculs!$B$31 -> 1750.7368 | E33: =C33+D33*(((1+Hypothèses!$B$54)^Hypothèses!$B$53-1)/Hypothèses!$B$54) -> 37561.804
B34: Propane | C34: =Hypothèses!$B$60 -> 7000 | D34: =Calculs!$B$32 -> 2346.6667 | E34: =C34+D34*(((1+Hypothèses!$B$54)^Hypothèses!$B$53-1)/Hypothèses!$B$54) -> 50645.451
B35: Élec direct (convecteurs) | C35: =Hypothèses!$B$61 -> 2000 | D35: =Calculs!$B$33 -> 2560.8 | E35: =C35+D35*(((1+Hypothèses!$B$54)^Hypothèses!$B$53-1)/Hypothèses!$B$54) -> 49628.099
B36: PAC retenue (net d'aides) | C36: =Calculs!$B$49 -> 7000 | D36: =Calculs!$B$34 -> 673.89474 | E36: =C36+D36*(((1+Hypothèses!$B$54)^Hypothèses!$B$53-1)/Hypothèses!$B$54) -> 19533.71
B38: Formule TCO : coût install + coût annuel × ((1 + inflation)^N − 1) / inflation
