Workbook

Sheet Hypothèses
A1: Hypothèses — Voiture électrique vs thermique 2026
A2: Barèmes 2026 (aides VE) et paramètres par défaut utilisés dans les 3 modes.
A4: Prime CEE « Coup de pouce VPE » 2026 — par tranche RFR/part
A5: Tranche RFR/part | B5: Montant prime (€)
A6: ≤ 16 300 € / part | B6: 5700
A7: 16 301 – 26 300 € / part | B7: 4700
A8: > 26 300 € / part | B8: 3500
D9: Source : LF 2026 — economie.gouv.fr / ecologie.gouv.fr
A10: Surbonus batterie fabriquée en UE (€)
A11: Non éligible | B11: 0
A12: Médian (option par défaut) | B12: 1500 | D12: Score environnemental ADEME
A13: Maximum (modèles haut de gamme) | B13: 2000
A15: Prix énergies — valeurs par défaut (€/kWh ou €/L)
A16: Électricité — heures creuses (€/kWh) | B16: 0.18 | D16: Tarif réglementé HC
A17: Électricité — heures pleines (€/kWh) | B17: 0.24 | D17: Tarif réglementé HP
A18: Électricité — borne rapide (€/kWh) | B18: 0.6 | D18: Bornes publiques DC
A19: Électricité — mix domicile (€/kWh, modes 2 & 3) | B19: 0.2 | D19: Hyp. moyenne foyer
A20: Essence SP95-E10 (€/L) | B20: 1.75 | D20: Moyenne 2026 — CGDD
A21: Diesel (€/L) | B21: 1.65 | D21: Moyenne 2026 — CGDD
A23: Décote moyenne (% du prix neuf conservé après détention)
A24: VE neuf — % conservé (5 ans) | B24: 0.45 | D24: Marché 2026 — indicatif
A25: Thermique neuf — % conservé (5 ans) | B25: 0.4 | D25: Marché 2026 — indicatif
A26: VE occasion — % conservé | B26: 0.55 | D26: Marché 2026 — indicatif
A27: Décote annuelle voiture actuelle (mode 2) | B27: 0.12 | D27: 12 %/an indicatif
A28: Taux décote actuelle mode 3 | B28: 0.88 | D28: Soit 1 − 12 %/an, facteur résiduel /an
A30: Entretien & assurance — valeurs par défaut (€/an)
A31: Entretien VE neuf | B31: 250 | D31: Moins de pièces d'usure
A32: Entretien VE occasion | B32: 300
A33: Entretien thermique neuf | B33: 600 | D33: Vidanges, courroie, etc.
A34: Entretien voiture actuelle | B34: 700
A35: Assurance VE neuf | B35: 650 | D35: Légèrement supérieure (+10-15 %)
A36: Assurance VE occasion | B36: 600
A37: Assurance thermique neuf | B37: 600
A38: Assurance voiture actuelle | B38: 550
A40: Borne de recharge à domicile
A41: Coût installation borne (€) | B41: 1200 | D41: Wallbox + pose
A42: Note : ce simulateur n'applique PAS de crédit d'impôt borne. | D42: Le crédit d'impôt 75 % plafonné à 500 € n'est pas modélisé ici.
A44: Hypothèses spécifiques au VE d'occasion
A45: Réserve pour risque batterie (€) | B45: 1500 | D45: Provision pour remplacement éventuel
A46: Facteur dégradation conso par 1 % SoH perdu | B46: 0.3 | D46: facteur = 1 + (1−SoH) × 0,3

Sheet Mode 1 — VE neuf vs th.
B1: Mode 1 — VE neuf vs voiture thermique neuve
B2: TCO sur durée de détention. Saisies en bleu, calculs noirs, KPI en bas.
B4: Votre usage
B5: Kilométrage annuel (km) | C5: 13000 | D5: Distance totale parcourue par an.
B6: Durée de détention (ans) | C6: 5 | D6: Sur combien d'années on calcule le TCO.
B8: Voiture électrique
B9: Prix VE catalogue TTC (€) | C9: 32000 | D9: Avant aides.
B10: Conso VE (kWh/100 km) | C10: 16 | D10: Citadine ≈14, SUV 18-22.
B11: Prime CEE VPE (€) | C11: 4700 | D11: 5 700 € (RFR/part ≤ 16 300) · 4 700 € (16 301-26 300) · 3 500 € (> 26 300).
B12: Surbonus batterie EU (€) | C12: 1500 | D12: 0, 1 500 ou 2 000 € selon modèle.
B13: Borne domicile (€) | C13: 1200 | D13: Installation wallbox.
B15: Voiture thermique
B16: Prix thermique catalogue TTC (€) | C16: 25000
B17: Carburant | C17: essence | D17: essence | diesel.
B18: Conso thermique (L/100 km) | C18: 6
B19: Malus CO₂ + poids (€) | C19: 0 | D19: 0 si modèle sobre.
B21: Prix de l'énergie (€/kWh ou €/L)
B22: Élec. heures creuses (€/kWh) | C22: 0.18
B23: Élec. heures pleines (€/kWh) | C23: 0.24
B24: Élec. borne rapide (€/kWh) | C24: 0.6
B25: Essence (€/L) | C25: 1.75
B26: Diesel (€/L) | C26: 1.65
B28: Mix de recharge VE (% — doit sommer à 100)
B29: Heures creuses (%) | C29: 70 | D29: Saisir en pourcentages entiers. Si la somme ≠ 100, le calcul renormalise.
B30: Heures pleines (%) | C30: 20
B31: Borne rapide (%) | C31: 10
B33: Entretien & assurance (€/an)
B34: Entretien VE | C34: 250
B35: Entretien thermique | C35: 600
B36: Assurance VE | C36: 650
B37: Assurance thermique | C37: 600
B39: Valeur de revente (% du prix neuf conservé)
B40: VE — % conservé | C40: 0.45 | D40: Cote indicative — à confronter à l'Argus du modèle.
B41: Thermique — % conservé | C41: 0.4
B44: Calculs intermédiaires
B45: Somme du mix (HC + HP + DC, %) | C45: =$C$29+$C$30+$C$31 -> 100 | D45: Le mix est exprimé en % entiers (ex : 70, 20, 10).
B46: Part HC effective (renormalisée) | C46: =IF(AND($C$45>0,ABS($C$45-100)>1),$C$29/$C$45,$C$29/100) -> 0.7 | D46: Renormalisé si somme ≠ 100.
B47: Part HP effective | C47: =IF(AND($C$45>0,ABS($C$45-100)>1),$C$30/$C$45,$C$30/100) -> 0.2
B48: Part DC effective | C48: =IF(AND($C$45>0,ABS($C$45-100)>1),$C$31/$C$45,$C$31/100) -> 0.1
B49: Prix kWh moyen (€/kWh) | C49: =$C$46*$C$22+$C$47*$C$23+$C$48*$C$24 -> 0.234 | D49: Moyenne pondérée selon le mix.
...

Sheet Mode 2 — Revente pour VE
B1: Mode 2 — Revendre la voiture actuelle pour un VE neuf
B2: Apport net, payback et bilan sur N ans (garder l'actuelle vs passer au VE).
B4: Voiture actuelle
B5: Valeur de revente (€) | C5: 8000 | D5: Estimation Argus / La Centrale.
B6: Carburant | C6: essence | D6: essence | diesel.
B7: Conso (L/100 km) | C7: 7
B8: Entretien (€/an) | C8: 700
B9: Assurance (€/an) | C9: 550
B10: Décote annuelle (%/an) | C10: 0.12 | D10: 12 %/an indicatif — fait référence dans Argus.
B12: Votre usage
B13: Kilométrage annuel (km) | C13: 13000
B14: Horizon d'analyse (ans) | C14: 5
B16: VE neuf visé
B17: Prix catalogue TTC (€) | C17: 32000
B18: Conso (kWh/100 km) | C18: 16
B19: Prime CEE VPE (€) | C19: 4700 | D19: 5 700 / 4 700 / 3 500 selon RFR/part.
B20: Surbonus batterie EU (€) | C20: 1500 | D20: 0, 1 500 ou 2 000.
B21: Borne domicile (€) | C21: 1200
B22: Entretien VE (€/an) | C22: 250
B23: Assurance VE (€/an) | C23: 650
B24: VE — % conservé après N ans | C24: 0.45
B26: Prix énergie
B27: kWh moyen domicile (€/kWh) | C27: 0.2 | D27: Mix HC/HP standard pour foyer.
B28: Essence (€/L) | C28: 1.75
B29: Diesel (€/L) | C29: 1.65
B32: Calculs intermédiaires
B33: Aides totales (€) | C33: =$C$19+$C$20 -> 6200
B34: Prix net VE (sans revente, €) | C34: =$C$17-$C$33+$C$21 -> 27000 | D34: Prix − aides + borne.
B35: Cash à sortir aujourd'hui (€) | C35: =$C$34-$C$5 -> 19000 | D35: Prix net VE − revente actuelle.
B36: Prix carburant retenu (€/L) | C36: =IF($C$6="essence",$C$28,$C$29) -> 1.75
B37: Actuelle — carburant /an (€) | C37: =$C$7/100*$C$13*$C$36 -> 1592.5
B38: Actuelle — usage total /an (€) | C38: =$C$37+$C$8+$C$9 -> 2842.5 | D38: Carburant + entretien + assurance.
B39: VE — recharge /an (€) | C39: =$C$18/100*$C$13*$C$27 -> 416
B40: VE — usage total /an (€) | C40: =$C$39+$C$22+$C$23 -> 1316
B41: Économie d'usage /an (€) | C41: =$C$38-$C$40 -> 1526.5 | D41: Garder − VE.
B42: Payback — années pour rentabiliser l'apport | C42: =IF(AND($C$41>0,$C$35>0),$C$35/$C$41,IF($C$35<=0,0,"Jamais")) -> 12.446774 | D42: 0 si apport ≤ 0, « Jamais » sinon.
B43: Actuelle — valeur résiduelle après N ans (€) | C43: =$C$5*(1-$C$10)^$C$14 -> 4221.8553 | D43: Décroissance géométrique au taux annuel.
B44: Actuelle — dépréciation cumulée (€) | C44: =$C$5-$C$43 -> 3778.1447
B45: VE — valeur résiduelle après N ans (€) | C45: =$C$17*$C$24 -> 14400
B46: TOTAL « garder l'actuelle » (€) | C46: =$C$44+$C$38*$C$14 -> 17990.645 | D46: Dépréciation + N × usage.
...

Sheet Mode 3 — VE occasion
B1: Mode 3 — Passer au VE d'occasion
B2: Sans aide nationale : c'est l'écart prix occasion / revente actuelle qui finance.
B4: Voiture actuelle
B5: Valeur de revente (€) | C5: 8000
B6: Carburant | C6: essence | D6: essence | diesel.
B7: Conso (L/100 km) | C7: 7
B8: Entretien (€/an) | C8: 700
B9: Assurance (€/an) | C9: 550
B11: Votre usage
B12: Kilométrage annuel (km) | C12: 13000
B13: Horizon d'analyse (ans) | C13: 5
B15: VE d'occasion visé
B16: Prix d'achat (€) | C16: 18000
B17: Âge (ans) | C17: 4 | D17: Au moment de l'achat.
B18: Km au compteur | C18: 60000 | D18: Information indicative.
B19: État batterie SoH (%) | C19: 0.9 | D19: ≥ 90 % excellent · 80-89 % correct · < 80 % dégradée.
B20: Conso annoncée (kWh/100 km) | C20: 17
B21: Borne domicile (€) | C21: 1200
B22: Réserve risque batterie (€) | C22: 1500 | D22: Provision en cas de remplacement.
B23: Entretien VE (€/an) | C23: 300
B24: Assurance VE (€/an) | C24: 600
B25: VE — % conservé après N ans | C25: 0.55
B27: Prix énergie
B28: kWh moyen domicile (€/kWh) | C28: 0.2
B29: Essence (€/L) | C29: 1.75
B30: Diesel (€/L) | C30: 1.65
B33: Calculs intermédiaires
B34: Coût brut VE (prix + borne + réserve) | C34: =$C$16+$C$21+$C$22 -> 20700
B35: Cash à sortir (apport net, €) | C35: =$C$34-$C$5 -> 12700 | D35: Coût brut VE − revente actuelle.
B36: Facteur conso lié à SoH | C36: =1+(1-$C$19)*Hypothèses!$B$46 -> 1.03 | D36: 1 + (1 − SoH) × 0,3 — augmente la conso pour batterie usée.
B37: Conso VE effective (kWh/100 km) | C37: =$C$20*$C$36 -> 17.51 | D37: Conso annoncée × facteur SoH.
B38: Prix carburant retenu (€/L) | C38: =IF($C$6="essence",$C$29,$C$30) -> 1.75
B39: Actuelle — carburant /an (€) | C39: =$C$7/100*$C$12*$C$38 -> 1592.5
B40: Actuelle — usage total /an (€) | C40: =$C$39+$C$8+$C$9 -> 2842.5
B41: VE — recharge /an (€) | C41: =$C$37/100*$C$12*$C$28 -> 455.26
B42: VE — usage total /an (€) | C42: =$C$41+$C$23+$C$24 -> 1355.26
B43: Économie d'usage /an (€) | C43: =$C$40-$C$42 -> 1487.24
B44: Payback (années) | C44: =IF(AND($C$43>0,$C$35>0),$C$35/$C$43,IF($C$35<=0,0,"Jamais")) -> 8.5393077
B45: Actuelle — résiduel après N ans (€) | C45: =$C$5*Hypothèses!$B$28^$C$13 -> 4221.8553 | D45: Mode 3 utilise un taux résiduel annuel fixe (0,88 = −12 %/an).
B46: Actuelle — dépréciation cumulée (€) | C46: =$C$5-$C$45 -> 3778.1447
...

Sheet Synthèse
B1: Synthèse — comparaison des 3 modes
B2: Récapitulatif des KPI principaux. Modifiez les saisies dans chaque feuille de mode.
B4: Indicateur | C4: Mode 1 (VE neuf vs th.) | D4: Mode 2 (revente pour VE) | E4: Mode 3 (VE occasion)
B5: TCO / Total — scénario alternatif | C5: ='Mode 1 — VE neuf vs th.'!$C$62 -> 19533.6 | D5: ='Mode 2 — Revente pour VE'!$C$47 -> 19180 | E5: ='Mode 3 — VE occasion'!$C$49 -> 13354.445
B6: TCO / Total — scénario de référence | C6: ='Mode 1 — VE neuf vs th.'!$C$63 -> 27825 | D6: ='Mode 2 — Revente pour VE'!$C$46 -> 17990.645 | E6: ='Mode 3 — VE occasion'!$C$48 -> 17990.645
B7: Écart en faveur du scénario alternatif | C7: ='Mode 1 — VE neuf vs th.'!$C$64 -> 8291.4 | D7: ='Mode 2 — Revente pour VE'!$C$48 -> -1189.3553 | E7: ='Mode 3 — VE occasion'!$C$50 -> 4636.2
B8: Économie d'usage / an | C8: ='Mode 1 — VE neuf vs th.'!$C$66 -> 1178.28 | D8: — | E8: —
B9: Apport net (cash à sortir) | C9: — | D9: ='Mode 2 — Revente pour VE'!$C$35 -> 19000 | E9: ='Mode 3 — VE occasion'!$C$35 -> 12700
B10: Bascule / payback (années) | C10: ='Mode 1 — VE neuf vs th.'!$C$67 -> 1.6973894 | D10: ='Mode 2 — Revente pour VE'!$C$42 -> 12.446774 | E10: ='Mode 3 — VE occasion'!$C$44 -> 8.5393077
B11: Risque batterie | C11: — | D11: — | E11: ='Mode 3 — VE occasion'!$C$52 -> faible
B13: Note : | C13: « Scénario alternatif » = VE neuf (mode 1) / passer au VE neuf (mode 2) / VE d'occasion (mode 3).
C14: « Scénario de référence » = thermique neuf (mode 1) / garder l'actuelle (modes 2 et 3).
